Workbook
Name ConveyorType: #REF!
Name StationType: [1]!Table6[Description]

Sheet Pivot
A3: Count of Rev.No. | B3: Column Labels
A4: Row Labels | B4: Config | C4: Devlopment | D4: Grand Total
A5: 46003 | C5: 1 | D5: 1
A6: 46029 | B6: 1 | C6: 1 | D6: 2
A7: 46035 | B7: 1 | D7: 1
A8: 46043 | B8: 1 | D8: 1
A9: 46045 | C9: 1 | D9: 1
A10: 46105 | B10: 1 | D10: 1
A11: 46157 | B11: 1 | D11: 1
A12: 46184 | B12: 2 | D12: 2
A13: 46198 | B13: 1 | D13: 1
A14: 46199 | B14: 1 | D14: 1
A15: 46209 | B15: 1 | D15: 1
A16: Grand Total | B16: 10 | C16: 3 | D16: 13

Sheet Revision
B2: Sr.No. | C2: Date | D2: Rev.No. | E2: Description of revision | F2: Change Type | G2: Attendee | H2: Remarks | J2: Change Type
B3: 1 | C3: 45790 | D3: 1 | E3: Initial draft | F3: Pre Release | G3: Ganesh K | H3: Initial draft | J3: Pre Release | K3: During Concept related changes
B4: 2 | C4: 45867 | D4: 1.1 | E4: as per flow ICD updated in various station | F4: Pre Release | G4: Raja, Kautubha, Vishal, Ganesh | J4: Development | K4: During development, the changes were made to simplify mWCS and PLC implementation and were documented in the ICD
B5: 3 | C5: 45895 | D5: 1.2 | E5: Below var added StackDestackStation- Abort, Abort_Ack LabellingStation- Pallet_Labelling_Status_Ack WrapUnwrapStation- Wrapping_Status UnloadingStation- Type_of_Operation | F5: Pre Release | G5: Ganesh K | J5: Conceptual & Architectural | K5: Changes related to pallet flow,architecture, and concept
B6: 4 | C6: 45937 | D6: 1.3 | E6: All area station master sheets added | F6: Pre Release | G6: Ganesh K | J6: Config | K6: Congfiguration realted Change
B7: 5 | C7: 45945 | D7: 1.4 | E7: abort and its ack added in conveyor station and cross transfer station | F7: Pre Release | G7: Ganesh K
B8: 6 | C8: 45972 | D8: 1.5 | E8: ElevatorStation added | F8: Pre Release | G8: Ganesh K
B9: 7 | C9: 45989 | D9: 1.6 | E9: Pallet_Status variable added in profile check station | F9: Pre Release | G9: Rohit P
B10: 8 | C10: 45995 | D10: 1.7 | E10: GTP decision station added | F10: Pre Release | G10: Ganesh K
B11: 9 | C11: 46003 | D11: 1.8 | E11: • In the "PLC ↔ WCS ICD" sheet, the below ICDs have been added for logging purposes only. CNV_Movimot_Drive STR_Lifter_Movimot_Drive STR_Gripper_Movimot_Drive CT_Mofivit_Drive CT_Moviswitch_Drive CNV_Barcode_Scanner CT_Barcode_Scanner Inbound_Main_Panel_Error_Mgr Inbound_Branch_Error_Manager Inbound_Safety_Door Inbound_Cross_Over • In the "Inbound" sheet, the above ICDs were added in the Functionality3 column, and a "Barcode Present" column was also added. | F11: Development | G11: Ganesh K | H11: Variable added for diagnostic logging purposes only, to easier issue identification and tracking ICD Release & Shared With Mukunda Haveris, Abhijeet Phatak & Raja Date 16-12-2025
B12: 10 | C12: 46029 | D12: 1.8.1 | E12: Loading Station ICD: Removed extra space from the Loading_Type variable. Stack De-stack Station ICD: Removed extra space from the Loading_Type variable. Wrap/Unwrap Station ICD: Corrected spelling of the Pallet_Operation_Status variable. Separator Station ICD: Corrected spelling of the Pallet_Operation_Status variable. | F12: Development | G12: Ganesh K | H12: Extra Space removed & Spelling corrected.
B13: 11 | C13: 46029 | D13: 1.8.2 | E13: Updated "Prod G 10M AMB" & "Prod G+1 10M AMB" sheet for source & destination requirment | F13: Config | G13: Vishal, Ganesh K | H13: Related areas are on hold from the customer side.
B14: 12 | C14: 46035 | D14: 1.8.3 | E14: • Below variables data type changed from bool to byte Request_For_Labelling_ACK Request_For_Operation_ACK | F14: Config | G14: Ganesh K | H14: Only the data type was corrected
B15: 13 | C15: 46043 | D15: 1.8.4 | E15: Pallet_ID_From_WCS: change string length from 35 to 10 Pallet_ID_From_PLC: change string length from 35 to 10 Vendor_Pallet_ID_From_PLC: change string length from 35 to 50 "Note" sheet modified for Source and destination requirement "SeparatorStationIP[X].Pallet_type" variable remark added | F15: Config | G15: Ganesh K | H15: Updated to comply with the customer pallet ID length of 10 characters
B16: 14 | C16: 46045 | D16: 1.9 | E16: • In the ASRS, OB to Man Unwrapping, GTP, Outbound, Flammable, Prod G AMB, Prod G Cold, Prod G floor, Prod G+1&2 AMB, Prod G+1&2 Cold, Prod G 10M AMB and Prod G+1 10M AMB sheets added Functionality3 column, and a "Barcode Present" column. | F16: Development | G16: Ganesh K | H16: Variable added for diagnostic logging purposes only, to easier issue identification and tracking
B17: 15 | C17: 46105 | D17: 1.10 | E17: Redundancy sheet added | F17: Config | G17: Mahesh Joshi | H17: Conceptualisation was pending as it needs discussion with mWCs team
B18: 16 | C18: 46157 | D18: 1.11 | E18: Below mentioned changes are updated during testing on site 1. Updated description for pallet "Profile_Status" variable ( no-9) 2. Updated description for "Type_of_Operation" varibale for loading, unloading & stacke_Destack stations 3. Added 64 no in "State" of unloading station 4. Updated description for "Vendor_Pallet_ID_From_PLC" in profile check station 5. Station master updated as per changes on site | F18: Config | G18: Vishal, Ganesh K, Mukunda | H18: The changes were implemented in the mWCS and PLC during testing and have been documented in the ICD.
B19: 17 | C19: 46184 | D19: 1.12 | E19: " PLC Zone Interface" ICD updated --- Removed conveyor_numbers | F19: Config | G19: Vishal, Ganesh K | H19: Conveyor no. Not required (This is related to redundancy logic)
B20: 18 | C20: 46184 | D20: 1.13 | E20: In GTP, B88C1, B88C2, B88C4, B93C1 & B93C2 station removed | F20: Config | G20: Vishal, Ganesh K, Kaustubh, Raja | H20: As agreed during the discussion with Raja, Mukunda H., Kaustubh Bapat, and Abhijit Phatak, unused stations (conveyors) were removed from the Station Master, as they are unable to accommodate full pallets - Layout issue - only config change on mWCS side
B21: 19 | C21: 46198 | D21: 1.14 | E21: In EZ9: B86C1, B80C1 & EZ8: B64C1 stations removed | F21: Config | G21: Ajay K, Abhijeet, Mukunda | H21: Based on the recommendation of Abhijit Phatak and Mukunda Ji, the decision points associated with stations B86C1, B80C1, and B64C1 have been removed. (This is done to easy handling of Source / destination on mWCS side)- Only Configuration change in mWCS side
B22: 20 | C22: 46199 | D22: 1.15 | E22: EZ8:B61C7,B61C8,B61C9,B62C1,B62C2 EZ9:B77C7,B77C8,B77C9,B78C1,B78C2,B78C3 Stations has been removed | F22: Config | G22: Ajay K, Abhijeet, Mukunda | H22: As discussed on Site B61C7,B61C8,B61C9,B62C1,B62C2,B77C7,B77C8,B77C9,B78C1,B78C2,B78C3 Decision Points has been removed (mWCS no need to give source & destination for this station) - This was tested at site in May26 on Both sides; but not modified in ICD.- only config change on mWCS side
B23: 21 | C23: 46209 | D23: 1.16 | E23: EZ6:B40C1, B38C3 EZ8:B59C1, B60C1,B68C1,B69C1 EZ9:B75C1, B76C1, B84C1, B85C1 Stations has been removed | F23: Config | G23: Ajay K, Abhijeet, Mukunda | H23: There is no change required from mWCS & PLC, also tested on site & NVIDIA, unused station has been removed from station master - Layout issue only config change on mWCS side
B24: 22 | C24: 46244 | D24: 1.17 | E24: 1. Reamark Updated 2. Same Index no used for Unloaidng Station B158C2 (31) & B90C1 (31), It changed for B90C1 (47) 3. PLC Warning No varibale added for all stations 4. All Zones Branch Error manager added in station manager | F24: Config | G24: Ajay K, Mukunda | H24: 1. Need to change B90C1 Unloading Station Index No 2. Need to use Warning tags for warning no logging in mWCS & PLC mapped all the tags to respective stations

Sheet Redundancy
B2: Zone | C2: Conveyor No | D2: Default finction | E2: Redundant function | F2: Remarks
B3: EZ1- Inbound Line | C3: B8C1 | D3: Not Used | E3: Out- to Fork AMR | F3: Redundant functionality by Default, but will not be any command from mWCS
C4: B9C1 | D4: Not Used | E4: Out- to Fork AMR | F4: Redundant functionality by Default, but will not be any command from mWCS
C5: B8C2 | D5: Not Used | E5: Out- to Zeron AMR | F5: Redundant functionality by Default, but will not be any command from mWCS
C6: B9C2 | D6: Not Used | E6: Out- to Zeron AMR | F6: Redundant functionality by Default, but will not be any command from mWCS
B8: EZ2- Inbound Line | C8: B13C4 | D8: Not Used | E8: In- From Zeron AMR | F8: Redundant functionality by Default, but will not be any command from mWCS
C9: B14C1 | D9: Not Used | E9: In- From Zeron AMR | F9: Redundant functionality by Default, but will not be any command from mWCS
C10: B16C1 | D10: Not Used | E10: Out- to Zeron AMR | F10: Redundant functionality by Default, but will not be any command from mWCS
C11: B16C1 | D11: Not Used | E11: Out- to Zeron AMR | F11: Redundant functionality by Default, but will not be any command from mWCS
C12: B18C1 | D12: Out- to Zeron AMR if Varo installed else No use | E12: Out- to Zeron AMR | F12: Redundant functionality by Default, but will not be any command from mWCS
C13: B19C4 | D13: Not Used | E13: In- From Zeron AMR | F13: Redundant functionality by Default, but will not be any command from mWCS
C14: B20C3 | D14: Not Used | E14: In- From Zeron AMR | F14: Redundant functionality by Default, but will not be any command from mWCS
C15: B21C1 | D15: Not Used | E15: Out- to Zeron AMR | F15: Redundant functionality by Default, but will not be any command from mWCS
C16: B22C1 | D16: Not Used | E16: Out- to Zeron AMR | F16: Redundant functionality by Default, but will not be any command from mWCS
B18: EZ3- Outbound Line | C18: B23C1 | D18: Out- to Fork AMR | E18: In- From Fork AMR | F18: Selectable from mWCS UI ( Conveyor wise)
C19: B24C1 | D19: Out- to Fork AMR | E19: In- From Fork AMR | F19: Selectable from mWCS UI ( Conveyor wise)
C20: B25C1 | D20: Out- to Fork AMR | E20: In- From Fork AMR | F20: Selectable from mWCS UI ( Conveyor wise)
C21: B26C1 | D21: Out- to Fork AMR | E21: In- From Fork AMR | F21: Selectable from mWCS UI ( Conveyor wise)
C22: B28C2 | D22: Not Used | E22: Out- to Zeron AMR | F22: Redundant functionality by Default, but will not be any command from mWCS
C23: B29C3 | D23: Not Used | E23: Out- to Zeron AMR | F23: Redundant functionality by Default, but will not be any command from mWCS
C24: B26C5 | D24: Not Used | E24: Not Used | F24: Functionality not known
B26: EZ4- Flamable Area | C26: B33C1, B33C3 | D26: Out- to Fork AMR | E26: In-from Fork AMR | F26: Selectable from mWCS UI ( Conveyor wise)
C27: BC179( Buffer conveyor) | D27: Out bound | E27: In bound | F27: mWCS to inform logiq about functionality change. Also ICD with EZ4 Conveyor will change
C28: B34C2, B34C3 | D28: In-from Fork AMR | E28: Out- to Fork AMR | F28: Selectable from mWCS UI ( Conveyor wise)
C29: BC180( Buffer conveyor) | D29: In bound | E29: Out bound | F29: mWCS to inform logiq about functionality change. Also ICD with EZ4 Conveyor will change
B31: EZ10- GTP | F31: No redundancy Option
B32: EZ17- Manual unwraping Line | F32: No redundancy Option
B35: EZ5- Ambient G floor area | C35: VT13 & VT22 OR B131C2 & B138C2 | D35: OUT bound from ASRS | E35: Are redundant for each other | F35: Redundant functionality by Default, but will not be any command from mWCS
C36: VT12 & BC-174 ( B117C2) | D36: Inbound for ASRS | E36: in case VF12 is down, Pallet wiil be loaded from B117C2 & Then 4way sshuttle will take the pallety to VT13/ VT22 & then pallet will be moved to other floors for storage' | F36: mWCS to inform logiq about functionality change. Also ICD with EZ4 Conveyor will change
C37: B171C1 | D37: PM Outbound for jeri-cans | E37: B131C2 & B138C2 will serve as jerican Outbound | F37: Redundant functionality by Default, but will not be any command from mWCS
B39: EZ6- Production G floor area | C39: EL16 & EL17 | D39: EL16 & EL17 | E39: Are redundant for each other | F39: Redundant functionality by Default, but will not be any command from mWCS
B41: EZ7- Cold G floor area | C41: VT15 | D41: Outbound | F41: No redundancy Option
C42: VT14 & BC-177 ( B45C2) | D42: Inbound for ASRS | E42: in case VF14 is down, Pallet wiil be loaded from B45c2 & Then 4way shuttle will take the pallety to VT15 & then pallet will be moved to other floors for storage | F42: mWCS to inform logiq about functionality change. Also ICD with EZ7 Conveyor will change
B44: EZ8- Prod G+1&2 Ambient | C44: VT12 & VT13 | D44: VT12, B61C7, B61C8 -Inbound VT13, B61C1, B61C2 - Outbound B61C9- Not used | E44: 1) If VT12 / B61C7/ B61C8 is down, then VT13,B61C1, B61C2- will work as inbound + Outbound. B61C9- Bidirectional depending on pallet flow. 2) If VT13/B61C1/ B61C2,is down, then VT12,B61C7, B61C8 - will work as inbound + Outbound B61C9- Bidirectional depending on pallet flow | F44: mWCS to inform logiq about functionality change. Also ICD with EZ8 Conveyor will change
B46: EZ9-Prod G+1&2 Cold | C46: VT14 & VT15 | D46: VT14, B77C7, B77C8, B77C9 -Inbound VT15, B78C1, B78C2, B78C3 - Outbound B78C10- Not used | E46: 1) If VT14/ B77C7/ B77C8/ B77C9 is down, then VT15/ B78C1/ B78C2/ B78C3- will work as inbound + Outbound. B78C10- Bidirectional depending on pallet flow. 2) If VT15/ B78C1/ B78C2/ B78C3,is down, then VT14/ B77C7/ B77C8/ B77C9 - will work as inbound + Outbound B61C9- Bidirectional depending on pallet flow | F46: mWCS to inform logiq about functionality change. Also ICD with EZ9 Conveyor will change
B51: EZ15- Prod G 10M AMB | F51: Hold From customer side
B54: EZ16- Prod G+1 10M AMB | F54: Hold From customer side

Sheet Note
B2: Below abbreviation is only for CT and TT
B3: 2 | C3: 14 | D3: 1
B4: Type of entity 1 - Cross Transfer; 2 - Turn Table | C4: Branch No | D4: TT/CT No
B7: NOTE: consider below station ICD variables if "Source requirement" coloum contain "Yes"
B8: Source
B9: Read_Source
B10: Read_Source_Ack
B11: Loading_Type
B12: Type_of_Operation
B13: Read_Loading_type
B14: Read_Loading_type_Ack
B16: NOTE: consider below station ICD variables if "Destination requirement" coloum contain "Yes"
B17: Request_For_Destination
B18: Destination
B19: Request_For_Destination_Ack
... B26: Request_For_Unloading_type_Ack

Sheet PLC ↔ WCS ICD
A1: Conveyor ( x is PLC no) X= 1 to 2 | B1: Common Interface | C1: Data type | D1: Conveyor PLC | E1: WCS | F1: Comment | G1: Recovery Comments | H1: Remark | I1: Raja comments
A2: ConveyorOP[X] | B2: PLCPowerOn | C2: Byte | D2: W | E2: R | F2: This byte conveys to WCS that PLC is powered on as follow: Stacker PLC will write in this byte 0= Power Off 1= Power On
A3: ConveyorIP[X] | B3: HeartBitIP | C3: Byte | D3: R | E3: W | F3: WCS will toggle values in this variable with 1 sec internal i.e. 1 and 2 IF this value change stops for 1 sec then generate error
A4: Zone ( x is zone no) X=1 to 94 | B4: PLC Zone Interface | C4: Data type | D4: Conveyor PLC | E4: WCS | F4: Comment | H4: Remark
A5: ZoneOP[X]. | B5: Mode | C5: Byte | D5: W | E5: R | F5: 1: Zone is in auto mode 2: Zone is in manual mode
A6: ZoneOP[X]. | B6: PLC_Error_No | C6: Int | D6: W | E6: R | F6: PLC will write error number in this variable at every stations. 0= No error Greater than 0 = system in fault
A7: ZoneIP[X]. | B7: Function | C7: Byte | D7: R | E7: W | F7: 1: Zone/Station to be used as Loading Station 2: Zone/Station to be used as UnLoading Station This will be read by PLC when no cycle is running & WCS give "Read_Function" signal | H7: If zone/staion is to be used as L/U station, then only this function related handshake is required & same will be monitored in PLC as well as WCS…. Otherwise station will work independantly.
A8: ZoneIP[X]. | B8: ConveyorNo | C8: Int | D8: R | E8: W | F8: WMS will give loading or unloading conveyor no based on Function Selection When loading Function Selected : B17C1, B71C2 : conveyor respctive ID to be written as per station master When Unloading Function Selected : B79C3, B14C1 : conveyor respctive ID to be written as per station master
A9: ZoneIP[X]. | B9: Read_function | C9: BOOL | D9: R | E9: W | F9: 1: After giving function, WCS will set this bit 0: Default OR False After getting "Read_function_Ack"
A10: ZoneOP[X]. | B10: Read_function_Ack | C10: Byte | D10: W | E10: R | F10: 1: After getting "Read_Function" this will be set by PLC, if function changed succefully 2: After getting "Read_Function" this will be set by PLC, if function not changed succefully. 0: After getting "Read_Function" OFF this will be made low
A11: Station ID (X is the ID of Station) X= 1 to 170 | B11: Loading Station | C11: Data type | D11: Conveyor PLC | E11: WCS | F11: Comment | H11: Remark
A12: LoadingStationOP[X]. | B12: Mode | C12: Byte | D12: W | E12: R | F12: 0: No Mode 1: Auto 2: Manual
A13: LoadingStationOP[X]. | B13: State | C13: Byte | D13: W | E13: R | F13: PLC will always update current state to this byte at every stations and WCS will read. 1 = SP Ready to Receive 2= Receive in progress 4= Pallet Present @ fwd end & ready to transfer 5= Pallet Present @ rev end & ready to transfer 6= Pallet move up to end in progress 8= Transfer in Progress 16 = In error 32 =Un-usable : If any module goes beyond repair then operatoe will mark that module(here conveyor) as not usable from HMI..Same will be shared to WCS. Based on that WCS will give alternate path to pallet. (this facility is optional) 64 = Vendor/Ko Ready to Receive 128= Data changed in manual mode
A14: LoadingStationOP[X]. | B14: PLC_Error_No | C14: Int | D14: W | E14: R | F14: PLC will write error number in this variable at every stations. 0= No error Greater than 0 = system in fault
A15: LoadingStationOP[X]. | B15: PLC_Warning_No | C15: Int | D15: W | E15: R | F15: PLC will write warning number in this variable at every stations. 0= No error Greater than 0 = warning present
A16: LoadingStationIP[X]. | B16: Loading_Type | C16: Int | D16: R | E16: W | F16: * If this station is in line--- (e.g. B69C2, B54C2 etc.) WCS will write Source point as per connected stations i.e. WCS will write station ID ( Refer Station Master Sheet), same will become zero after "Pallet_Transferred" received from PLC. * If this station is standalone- (e.g B3C1, B4C1, B5C1 etc.) WCS will write loadig type based on loading device, same will become zero after "Pallet_Transferred" received from PLC. 0= Deafult/No action 1 = No loading station 2 = Manual Loading 3 = Automatic Loading-AMR 4 = Automatic Loading-Fork type AGV 5=Automatic Loading-Conveyor Top AMR | G16: • During handshake, if a power failure, mode change, or error occurs, this value is set to zero by the WCS. • Once the system is healthy and the handshake is not completed, all handshakes will start from the beginning. • Once the handshake is completed, this sequence does not need to start again until the next cycle.
A17: LoadingStationIP[X]. | B17: Type_of_Operation | C17: Int | D17: R | E17: W | F17: 1 = Single pallet loading ( Pallet will be loaded two times i.e. first system pallet & then vendor/KO pallet so with MWCS two times loading handshake is required e.g. B3C1, B4C1, B5C1) 2 = Multi pallet Loading (Pallet will be loaded once i.e. "KO + SP" or only SP pallet will be loaded at a time, so with MWCS one time loading handshake is required e.g. B6C1, B5C2, B35C1, B43C1, B47C1, B63C5, B69C5 etc) This information is required to pass on to PLC, so that PLC can wait for both pallet whenever required. | G17: • During handshake, if a power failure, mode change, or error occurs, this value is set to zero by the WCS. • Once the system is healthy and the handshake is not completed, all handshakes will start from the beginning. • Once the handshake is completed, this sequence does not need to start again until the next cycle.
A18: LoadingStationIP[X]. | B18: Read_Loading_type | C18: Byte | D18: R | E18: W | F18: 1= WCS will write this when it want to load pallet at loading station 99= WCS will set this value when"Read_Loading_type_Ack"=2 received from PLC. 0 = WCS will set this value when"Read_Loading_type_Ack"=0 received from PLC. | G18: • During handshake, if a power failure, mode change, or error occurs, this value is set to zero by the WCS. • Once the system is healthy and the handshake is not completed, all handshakes will start from the beginning. • Once the handshake is completed, this sequence does not need to start again until the next cycle. | H18: WCS will give "Read_Loading_type" & "Loading_type" signal two time i.e. one for SP Pallet & one for vendor pallet… This is to define whether AMR/Fpork Type AMR is coming to station
A19: LoadingStationOP[X]. | B19: Read_Loading_type_Ack | C19: Byte | D19: W | E19: R | F19: PLC Will write ACK to WCS. 0=will become zero after"Read_Loading_type" = 99 from WCS. 1= Spare; 2 = OK; | G19: • During handshake, if a power failure, mode change, or error occurs, this value is set to zero by the WCS. • Once the system is healthy and the handshake is not completed, all handshakes will start from the beginning. • Once the handshake is completed, this sequence does not need to start again until the next cycle.
A20: LoadingStationIP[X]. | B20: Pallet_ID_From_WCS | C20: String(10) | D20: R | E20: W | F20: 1. WCS will write system pallet ID , when value of state = 4 or 5"pallet receive in progress" "Pallet Present @end & ready to transfer". (After writing the pallet ID WCS will write space for remaing character in a string (i.e ASCII 32)) 2. WCS will clear(space) the data, at "Pallet_Transferred" =1 received from PLC.
A21: LoadingStationOP[X]. | B21: Request_For_Destination | C21: Byte | D21: W | E21: R | F21: 1= PLC will write this when Pallet is Received at every station. 99= PLC will set this value when"Request_For_Destination" ACK received from WCS except ack=1 (Wait). 0= will become zero after Request_For_Destination_Ack=0 from WCS | G21: • During handshake, if a power failure, mode change, or error occurs, this value is set to zero by the WCS. • Once the system is healthy and the handshake is not completed, all handshakes will start from the beginning. • If the handshake is completed and a power failure, mode change, or error occurs while the state is 4 or 5, then this sequence will repeat. • This handshake will continue to repeat until the state reaches 8.
A22: LoadingStationIP[X]. | B22: Destination | C22: Int | D22: R | E22: W | F22: 1. WCS will write Next Destination as per connected stations i.e. WCS will write station ID ( Refer Station Master Sheet), 2. same will become zero after "Pallet_Transferred"=99 received from PLC. | G22: • During handshake, if a power failure, mode change, or error occurs, this value is set to zero by the WCS. • Once the system is healthy and the handshake is not completed, all handshakes will start from the beginning. • If the handshake is completed and a power failure, mode change, or error occurs while the state is 4 or 5, then this sequence will repeat. • This handshake will continue to repeat until the state reaches 8.
A23: LoadingStationIP[X]. | B23: Request_For_Destination_Ack | C23: Byte | D23: R | E23: W | F23: WCS Will write Next Destination & then give ACK to PLC. 0=will become zero after"Request_For_Destination" 99 from PLC. 1= Wait; 2 = OK; | G23: • During handshake, if a power failure, mode change, or error occurs, this value is set to zero by the WCS. • Once the system is healthy and the handshake is not completed, all handshakes will start from the beginning. • If the handshake is completed and a power failure, mode change, or error occurs while the state is 4 or 5, then this sequence will repeat. • This handshake will continue to repeat until the state reaches 8.
A24: LoadingStationOP[X]. | B24: Pallet_Transferred | C24: Byte | D24: W | E24: R | F24: 1= PLC will write this when Pallet is transferred to next station at every stations. 99= PLC will set this value when Pallet Transferred ACK = 1 received from WCS. 0= will become zero after Pallet_Transferred_Ack=0 from WCS | G24: • During handshake, if a power failure, mode change, or error occurs, this value is set to zero by the WCS. • Once the system is healthy and the handshake is not completed, all handshakes will start from the beginning. • If the handshake is completed and a power failure, mode change, or error occurs while the state is 4 or 5, then this sequence will repeat.
A25: LoadingStationIP[X]. | B25: Pallet_Transferred_Ack | C25: Byte | D25: R | E25: W | F25: 1= WCS will write when received pallet transferred from PLC. 0= Default OR When Pallet Transferred received 99 from PLC. | G25: • During handshake, if a power failure, mode change, or error occurs, this value is set to zero by the WCS. • Once the system is healthy and the handshake is not completed, all handshakes will start from the beginning. • If the handshake is completed and a power failure, mode change, or error occurs while the state is 4 or 5, then this sequence will repeat.
A26: Station ID (X is the ID of Station) X= 1 to 189 | B26: Unloading Station (Single In) | C26: Data type | D26: Conveyor PLC | E26: WCS | F26: Comment | H26: Remark
A27: UnloadingStationOP[X]. | B27: Mode | C27: Byte | D27: W | E27: R | F27: 0: No Mode 1: Auto 2: Manual
A28: UnloadingStationOP[X]. | B28: State | C28: Byte | D28: W | E28: R | F28: PLC will always update current state to this byte at every stations and WCS will read. 1 = Ready to Receive 2= Receive in progress 4= Pallet Present @ fwd end & ready to transfer 5= Pallet Present @ rev end & ready to transfer 6= Pallet move up to end in progress 8= Transfer in Progress 16 = In error 32 =Un-usable : If any module goes beyond repair then operatoe will mark that module(here conveyor) as not usable from HMI..Same will be shared to WCS. Based on that WCS will give alternate path to pallet. (this facility is optional) 64 = System pallet ready to unload 128= Data changed in manual mode
A29: UnloadingStationOP[X]. | B29: PLC_Error_No | C29: Int | D29: W | E29: R | F29: PLC will write error number in this variable at every stations. 0= No error Greater than 0 = system in fault
A30: UnloadingStationOP[X]. | B30: PLC_Warning_No | C30: Int | D30: W | E30: R | F30: PLC will write warning number in this variable at every stations. 0= No warning Greater than 0 = warning present
A31: UnloadingStationIP[X]. | B31: Source | C31: Int | D31: R | E31: W | F31: * If this station is in line--- WCS will write Source point as per connected stations i.e. WCS will write station ID ( Refer Station Master Sheet), same will become zero after "Pallet_Transferred" received from PLC. * If this station is standalone- WCS will write unloadig type based on unloading device, same will become zero after "Pallet_Transferred" received from PLC. 0= Deafult/No action 1 = No Unloading station 2 = Manual UnLoading 3 = Automatic UnLoading-AMR 4 = Automatic UnLoading-Fork type AGV 5=Automatic UnLoading-Conveyor Top AMR | G31: • During handshake, if a power failure, mode change, or error occurs, this value is set to zero by the WCS. • Once the system is healthy and the handshake is not completed, all handshakes will start from the beginning. • Once the handshake is completed, this sequence does not need to start again until the next cycle.
A32: UnloadingStationIP[X]. | B32: Read_Source | C32: Byte | D32: R | E32: W | F32: 1= WCS will write this when it want to Unload pallet present at Unloading station 99= WCS will set this value when"Read_Source_Ack"=2 received from PLC. 0 = WCS will set this value when"Read_Source_Ack"=0 received from PLC. | G32: • During handshake, if a power failure, mode change, or error occurs, this value is set to zero by the WCS. • Once the system is healthy and the handshake is not completed, all handshakes will start from the beginning. • Once the handshake is completed, this sequence does not need to start again until the next cycle.
A33: UnloadingStationOP[X]. | B33: Read_Source_Ack | C33: Byte | D33: W | E33: R | F33: PLC Will write ACK to WCS. 0=will become zero after"Read_Source" = 99 from WCS. 1= Spare; 2 = OK; | G33: • During handshake, if a power failure, mode change, or error occurs, this value is set to zero by the WCS. • Once the system is healthy and the handshake is not completed, all handshakes will start from the beginning. • Once the handshake is completed, this sequence does not need to start again until the next cycle.
A34: UnloadingStationOP[X]. | B34: Request_For_Unloading_type | C34: Byte | D34: W | E34: R | F34: 1= PLC will write this when Pallet is Received at station 99= PLC will set this value when"Request_For_Unloading_type_ACK" received from WCS =2. 0 = PLC will set this value when"Request_For_Unloading_type_ACK" received from WCS =0. | G34: • During handshake, if a power failure, mode change, or error occurs, this value is set to zero by the WCS. • Once the system is healthy and the handshake is not completed, all handshakes will start from the beginning. • Once the handshake is completed, this sequence does not need to start again until the next cycle. | H34: Name changed
A35: UnloadingStationIP[X]. | B35: Type_of_Operation | C35: Byte | D35: R | E35: W | F35: 1 = Single pallet Unloading ( Pallet will be Unloaded two times i.e. first vendor/KO pallet & then system pallet, so with MWCS two times Unloading handshake is required e.g. B6C3, B39C1) This will come typically with fork type AMR 2 = Multi pallet Unloading (Pallet will be Unloaded once i.e. KO + SP pallet will be loaded at a time, so with MWCS one time loading handshake is required e.g. B53C2, B9C2 etc.) This information is required to pass on to PLC, so that PLC can wait for both pallet whenever required. | G35: • During handshake, if a power failure, mode change, or error occurs, this value is set to zero by the WCS. • Once the system is healthy and the handshake is not completed, all handshakes will start from the beginning. • Once the handshake is completed, this sequence does not need to start again until the next cycle. | H35: New var added on 29/08/2025
A36: UnloadingStationIP[X]. | B36: Reject_Reason | C36: Byte | D36: R | E36: W | F36: 1= Pallet length is not ok, 2= Pallet width is not ok, 3= Pallet length and Width is not ok 4= Pallet height is not ok 5= Pallet length and height is not ok 6= Pallet height and width is not ok 7= Pallet length,width and height is not ok 8= Profile ok. 9= Height Not ok for pallet wrapping 10=SP Barcode read Error 11=Vendor Barcode read Error 21= WCS_OK 22 = Reject because of SP pallet barcode 23 = Reject because of vendor Pallet barcode 24 = Reject because of weight 25= Reject because of Pallet type 26 = Reject because of Packing file not found (if applicable) 27 = Reject Because of Location not found (if applicable) 28 = Reject Because of Pallet Already in DO (if applicable) 29 = Reject Because of Pallet Already in Queue (if applicable) will become zero after "Pallet_Transferred" signal become zero | H36: 12-20 will spares (reference from profile check) 21= WCS_OK will only use in WPLS, will not share to PLC.
A37: UnloadingStationIP[X]. | B37: Unloading_type | C37: Int | D37: R | E37: W | F37: 1. WCS will write Next Unloading_type as per connected stations i.e. WCS will write station ID ( Refer Station Master Sheet), same will become zero after "Pallet_Transferred"=99 received from PLC. Note - Unloading_type No is as below 0= Deafult/No action 1 = No Unloading station 2 = Manual Unloading 3 = Automatic Unloading-AMR 4 = Automatic Unloading-Fork type AGV 5=Automatic Unloading-Conveyor Top AMR | G37: • During handshake, if a power failure, mode change, or error occurs, this value is set to zero by the WCS. • Once the system is healthy and the handshake is not completed, all handshakes will start from the beginning. • Once the handshake is completed, this sequence does not need to start again until the next cycle. | H37: Name changed
A38: UnloadingStationIP[X]. | B38: Request_For_Unloading_type_Ack | C38: Byte | D38: R | E38: W | F38: WCS Will write Next Unloading_type & then give ACK to PLC. 0=will become zero after"Request_For_Unloading_type" 99 from PLC. 1= Wait; 2 = OK; | G38: • During handshake, if a power failure, mode change, or error occurs, this value is set to zero by the WCS. • Once the system is healthy and the handshake is not completed, all handshakes will start from the beginning. • Once the handshake is completed, this sequence does not need to start again until the next cycle.
A39: UnloadingStationOP[X]. | B39: Pallet_Transferred | C39: Byte | D39: W | E39: R | F39: 1= PLC will write this when Pallet is transferred to next station at every stations. 99= PLC will set this value when Pallet Transferred ACK = 1 received from WCS. 0= will become zero after Pallet_Transferred_Ack=0 from WCS | G39: • During handshake, if a power failure, mode change, or error occurs, this value is set to zero by the WCS. • Once the system is healthy and the handshake is not completed, all handshakes will start from the beginning. • If the handshake is completed and a power failure, mode change, or error occurs while the state is 4 or 5, then this sequence will repeat. | H39: After pallet unloaded by fork lift or by AGV, this signal will be given
A40: UnloadingStationIP[X]. | B40: Pallet_Transferred_Ack | C40: Byte | D40: R | E40: W | F40: 1= WCS will write when received pallet transferred from PLC. 0= Default OR When Pallet Transferred received 99 from PLC. | G40: • During handshake, if a power failure, mode change, or error occurs, this value is set to zero by the WCS. • Once the system is healthy and the handshake is not completed, all handshakes will start from the beginning. • If the handshake is completed and a power failure, mode change, or error occurs while the state is 4 or 5, then this sequence will repeat.
...

Sheet Station Details
B3: Name | C3: Inbound | D3: ASRS | E3: OB to Man Unwrapping | F3: GTP | G3: Outbound | H3: Flammable | I3: Prod G AMB | J3: Prod G Cold | K3: Prod G floor | L3: Prod G+1&2 AMB | M3: Prod G+1&2 Cold | N3: Prod G 10M AMB | O3: Prod G+1 10M AMB
B4: ConveyorStation | C4: ='EZ1 Inbound'!U7 -> 34 | D4: ='EZ2 ASRS'!U7 -> 38 | E4: ='EZ17 OB to Man Unwrapping'!U7 -> 30 | F4: ='EZ10 GTP'!U7 -> 21 | G4: ='EZ3 Outbound'!U7 -> 31 | H4: ='EZ4 Flammable'!U7 -> 5 | I4: ='EZ5 Prod G AMB'!U7 -> 36 | J4: ='EZ7 Prod G Cold'!U7 -> 42 | K4: ='EZ6 Prod G floor'!U7 -> 10 | L4: ='EZ8 Prod G+1&2 AMB'!U7 -> 49 | M4: ='EZ9 Prod G+1&2 Cold'!U7 -> 47 | N4: ='EZ15 Prod G 10M AMB'!U7 -> 21 | O4: ='EZ16 Prod G+1 10M AMB'!U7 -> 35 | P4: =SUM(C4:O4) -> 399
B5: CrossTransferStation | C5: ='EZ1 Inbound'!U8 -> 8 | D5: ='EZ2 ASRS'!U8 -> 12 | E5: ='EZ17 OB to Man Unwrapping'!U8 -> 5 | F5: ='EZ10 GTP'!U8 -> 7 | G5: ='EZ3 Outbound'!U8 -> 9 | H5: ='EZ4 Flammable'!U8 -> 1 | I5: ='EZ5 Prod G AMB'!U8 -> 10 | J5: ='EZ7 Prod G Cold'!U8 -> 6 | K5: ='EZ6 Prod G floor'!U8 -> 6 | L5: ='EZ8 Prod G+1&2 AMB'!U8 -> 14 | M5: ='EZ9 Prod G+1&2 Cold'!U8 -> 15 | N5: ='EZ15 Prod G 10M AMB'!U8 -> 6 | O5: ='EZ16 Prod G+1 10M AMB'!U8 -> 7 | P5: =SUM(C5:O5) -> 106
B6: Decision | C6: ='EZ1 Inbound'!U9 -> 8 | D6: ='EZ2 ASRS'!U9 -> 12 | E6: ='EZ17 OB to Man Unwrapping'!U9 -> 4 | F6: ='EZ10 GTP'!U9 -> 5 | G6: ='EZ3 Outbound'!U9 -> 9 | H6: ='EZ4 Flammable'!#REF! -> #REF! | I6: ='EZ5 Prod G AMB'!U9 -> 9 | J6: ='EZ7 Prod G Cold'!U9 -> 6 | K6: ='EZ6 Prod G floor'!U9 -> 3 | L6: ='EZ8 Prod G+1&2 AMB'!U9 -> 15 | M6: ='EZ9 Prod G+1&2 Cold'!U9 -> 21 | N6: ='EZ15 Prod G 10M AMB'!U9 -> 6 | O6: ='EZ16 Prod G+1 10M AMB'!U9 -> 11 | P6: =SUM(C6:O6) -> #REF!
B7: LoadingStation | C7: ='EZ1 Inbound'!U10 -> 5 | D7: ='EZ2 ASRS'!U10 -> 4 | E7: ='EZ17 OB to Man Unwrapping'!U10 -> 0 | F7: ='EZ10 GTP'!U10 -> 2 | G7: ='EZ3 Outbound'!U10 -> 9 | H7: ='EZ4 Flammable'!U9 -> 1 | I7: ='EZ5 Prod G AMB'!U10 -> 2 | J7: ='EZ7 Prod G Cold'!U10 -> 23 | K7: ='EZ6 Prod G floor'!U10 -> 2 | L7: ='EZ8 Prod G+1&2 AMB'!U10 -> 4 | M7: ='EZ9 Prod G+1&2 Cold'!U10 -> 4 | N7: ='EZ15 Prod G 10M AMB'!U10 -> 2 | O7: ='EZ16 Prod G+1 10M AMB'!U10 -> 2 | P7: =SUM(C7:O7) -> 60
B8: UnloadingStation | C8: ='EZ1 Inbound'!U11 -> 5 | D8: ='EZ2 ASRS'!U11 -> 5 | E8: ='EZ17 OB to Man Unwrapping'!U11 -> 3 | F8: ='EZ10 GTP'!U11 -> 3 | G8: ='EZ3 Outbound'!U11 -> 11 | H8: ='EZ4 Flammable'!U10 -> 1 | I8: ='EZ5 Prod G AMB'!U11 -> 3 | J8: ='EZ7 Prod G Cold'!U11 -> 22 | K8: ='EZ6 Prod G floor'!U11 -> 2 | L8: ='EZ8 Prod G+1&2 AMB'!U11 -> 6 | M8: ='EZ9 Prod G+1&2 Cold'!U11 -> 4 | N8: ='EZ15 Prod G 10M AMB'!U11 -> 1 | O8: ='EZ16 Prod G+1 10M AMB'!U11 -> 1 | P8: =SUM(C8:O8) -> 67
B9: StackDestackStation | C9: ='EZ1 Inbound'!U12 -> 4 | D9: ='EZ2 ASRS'!U12 -> 0 | E9: ='EZ17 OB to Man Unwrapping'!U12 -> 0 | F9: ='EZ10 GTP'!U12 -> 3 | G9: ='EZ3 Outbound'!U12 -> 4 | H9: ='EZ4 Flammable'!U11 -> 0 | I9: ='EZ5 Prod G AMB'!U12 -> 4 | J9: ='EZ7 Prod G Cold'!U12 -> 2 | K9: ='EZ6 Prod G floor'!U12 -> 1 | L9: ='EZ8 Prod G+1&2 AMB'!U12 -> 2 | M9: ='EZ9 Prod G+1&2 Cold'!U12 -> 2 | N9: ='EZ15 Prod G 10M AMB'!U12 -> 2 | O9: ='EZ16 Prod G+1 10M AMB'!U12 -> 1 | P9: =SUM(C9:O9) -> 25
B10: ProfileCheckStation | C10: ='EZ1 Inbound'!U13 -> 1 | D10: ='EZ2 ASRS'!U13 -> 0 | E10: ='EZ17 OB to Man Unwrapping'!U13 -> 0 | F10: ='EZ10 GTP'!U13 -> 0 | G10: ='EZ3 Outbound'!U13 -> 1 | H10: ='EZ4 Flammable'!U12 -> 0 | I10: ='EZ5 Prod G AMB'!U13 -> 2 | J10: ='EZ7 Prod G Cold'!U13 -> 2 | K10: ='EZ6 Prod G floor'!U13 -> 1 | L10: ='EZ8 Prod G+1&2 AMB'!U13 -> 2 | M10: ='EZ9 Prod G+1&2 Cold'!U13 -> 2 | N10: ='EZ15 Prod G 10M AMB'!U13 -> 2 | O10: ='EZ16 Prod G+1 10M AMB'!U13 -> 1 | P10: =SUM(C10:O10) -> 14
B11: TurnTableStation | C11: ='EZ1 Inbound'!U14 -> 0 | D11: ='EZ2 ASRS'!U14 -> 0 | E11: ='EZ17 OB to Man Unwrapping'!U14 -> 2 | F11: ='EZ10 GTP'!U14 -> 0 | G11: ='EZ3 Outbound'!U14 -> 0 | H11: ='EZ4 Flammable'!U13 -> 0 | I11: ='EZ5 Prod G AMB'!U14 -> 0 | J11: ='EZ7 Prod G Cold'!U14 -> 0 | K11: ='EZ6 Prod G floor'!U14 -> 0 | L11: ='EZ8 Prod G+1&2 AMB'!U14 -> 0 | M11: ='EZ9 Prod G+1&2 Cold'!U14 -> 0 | N11: ='EZ15 Prod G 10M AMB'!U14 -> 0 | O11: ='EZ16 Prod G+1 10M AMB'!U14 -> 1 | P11: =SUM(C11:O11) -> 3
B12: LabellingStation | C12: ='EZ1 Inbound'!U15 -> 1 | D12: ='EZ2 ASRS'!U15 -> 0 | E12: ='EZ17 OB to Man Unwrapping'!U15 -> 0 | F12: ='EZ10 GTP'!U15 -> 0 | G12: ='EZ3 Outbound'!U15 -> 1 | H12: ='EZ4 Flammable'!U10 -> 1 | I12: ='EZ5 Prod G AMB'!U15 -> 0 | J12: ='EZ7 Prod G Cold'!U15 -> 0 | K12: ='EZ6 Prod G floor'!U15 -> 0 | L12: ='EZ8 Prod G+1&2 AMB'!U15 -> 0 | M12: ='EZ9 Prod G+1&2 Cold'!U15 -> 0 | N12: ='EZ15 Prod G 10M AMB'!U15 -> 0 | O12: ='EZ16 Prod G+1 10M AMB'!U15 -> 0 | P12: =SUM(C12:O12) -> 3
B13: WrappingStation | C13: ='EZ1 Inbound'!U16 -> 1 | D13: ='EZ2 ASRS'!U16 -> 0 | E13: ='EZ17 OB to Man Unwrapping'!U16 -> 0 | F13: ='EZ10 GTP'!U16 -> 0 | G13: ='EZ3 Outbound'!U16 -> 1 | H13: ='EZ4 Flammable'!U11 -> 0 | I13: ='EZ5 Prod G AMB'!U16 -> 0 | J13: ='EZ7 Prod G Cold'!U16 -> 0 | K13: ='EZ6 Prod G floor'!U16 -> 0 | L13: ='EZ8 Prod G+1&2 AMB'!U16 -> 1 | M13: ='EZ9 Prod G+1&2 Cold'!U16 -> 0 | N13: ='EZ15 Prod G 10M AMB'!U16 -> 0 | O13: ='EZ16 Prod G+1 10M AMB'!U16 -> 1 | P13: =SUM(C13:O13) -> 4
B14: Zone | C14: ='EZ1 Inbound'!U17 -> 0 | D14: ='EZ2 ASRS'!U17 -> 0 | E14: ='EZ17 OB to Man Unwrapping'!U17 -> 0 | F14: ='EZ10 GTP'!U17 -> 1 | G14: ='EZ3 Outbound'!U17 -> 4 | H14: ='EZ4 Flammable'!U12 -> 0 | I14: ='EZ5 Prod G AMB'!U17 -> 0 | J14: ='EZ7 Prod G Cold'!U17 -> 21 | K14: ='EZ6 Prod G floor'!U17 -> 3 | L14: ='EZ8 Prod G+1&2 AMB'!U17 -> 2 | M14: ='EZ9 Prod G+1&2 Cold'!U17 -> 2 | N14: ='EZ15 Prod G 10M AMB'!U17 -> 0 | O14: ='EZ16 Prod G+1 10M AMB'!U17 -> 1 | P14: =SUM(C14:O14) -> 34
B15: SeparatorStation | C15: ='EZ1 Inbound'!U18 -> 0 | D15: ='EZ2 ASRS'!U18 -> 0 | E15: ='EZ17 OB to Man Unwrapping'!U18 -> 0 | F15: ='EZ10 GTP'!U18 -> 2 | G15: ='EZ3 Outbound'!U18 -> 0 | H15: ='EZ4 Flammable'!U13 -> 0 | I15: ='EZ5 Prod G AMB'!U18 -> 5 | J15: ='EZ7 Prod G Cold'!U18 -> 3 | K15: ='EZ6 Prod G floor'!V18 -> 0 | L15: ='EZ8 Prod G+1&2 AMB'!U18 -> 0 | M15: ='EZ9 Prod G+1&2 Cold'!U18 -> 0 | N15: ='EZ15 Prod G 10M AMB'!U18 -> 3 | O15: ='EZ16 Prod G+1 10M AMB'!U18 -> 1 | P15: =SUM(C15:O15) -> 14
B16: ElevatorStation | C16: ='EZ1 Inbound'!U19 -> 0 | D16: ='EZ2 ASRS'!U19 -> 0 | E16: ='EZ17 OB to Man Unwrapping'!U19 -> 0 | F16: ='EZ10 GTP'!U19 -> 0 | G16: ='EZ3 Outbound'!U19 -> 0 | H16: ='EZ4 Flammable'!V14 -> 0 | I16: ='EZ5 Prod G AMB'!U19 -> 0 | J16: ='EZ7 Prod G Cold'!U19 -> 0 | K16: ='EZ6 Prod G floor'!V19 -> 2 | L16: ='EZ8 Prod G+1&2 AMB'!U19 -> 0 | M16: ='EZ9 Prod G+1&2 Cold'!U19 -> 2 | N16: ='EZ15 Prod G 10M AMB'!U19 -> 0 | O16: ='EZ16 Prod G+1 10M AMB'!U19 -> 0 | P16: =SUM(C16:O16) -> 4
B17: GTPDecision | C17: 0 | D17: 0 | E17: 0 | F17: ='EZ10 GTP'!U18 -> 2 | G17: 0 | H17: 0 | I17: 0 | J17: 0 | K17: 0 | L17: 0 | M17: 0 | N17: 0 | O17: 0 | P17: =SUM(C17:O17) -> 2

Sheet EZ1 Inbound
A1: ID | B1: Name | C1: PLC ID | D1: Zone ID | E1: Functionality 1 with Array Index | F1: Functionality 2 with Array Index | G1: Functionality 3 with Array Index | H1: Functionality 4 with Array Index | I1: Functionality 5 with Array Index | J1: Functionality Logging purpose only | K1: Barcode Present (Yes/No) | L1: Source requirement | M1: Destination requirement | N1: Remarks
A2: =IF(ISNUMBER(SEARCH("CT",B2)),"1"&MID(B2,2,FIND("CT",B2)-2)&RIGHT(B2,1),MID(B2,2,FIND("C",B2)-2)&RIGHT(B2,1)) -> 31 | B2: B3C1 | C2: Inbound | D2: 1 | E2: =IF(ISNUMBER(SEARCH("CT",B2)), "CrossTransferStation[" & (Q$3 + COUNTIF($B$2:B2,"*CT*")-1) & "]", IF(AND(ISNUMBER(SEARCH("C",B2)),NOT(ISNUMBER(SEARCH("CT",B2)))), "ConveyorStation[" & (Q$2 + COUNTIF($B$2:B2,"*C*") - COUNTIF($B$2:B2,"*CT*")-1) & "]", "")) -> ConveyorStation[1] | F2: LoadingStation[1] | J2: CNV_Movimot_Drive[1] | K2: No | L2: Yes | M2: No | P2: CNC Start No | Q2: 1
A3: =IF(ISNUMBER(SEARCH("CT",B3)),"1"&MID(B3,2,FIND("CT",B3)-2)&RIGHT(B3,1),MID(B3,2,FIND("C",B3)-2)&RIGHT(B3,1)) -> 32 | B3: B3C2 | C3: Inbound | D3: 1 | E3: =IF(ISNUMBER(SEARCH("CT",B3)), "CrossTransferStation[" & (Q$3 + COUNTIF($B$2:B3,"*CT*")-1) & "]", IF(AND(ISNUMBER(SEARCH("C",B3)),NOT(ISNUMBER(SEARCH("CT",B3)))), "ConveyorStation[" & (Q$2 + COUNTIF($B$2:B3,"*C*") - COUNTIF($B$2:B3,"*CT*")-1) & "]", "")) -> ConveyorStation[2] | F3: StackDestackStation[3] | J3: CNV_Movimot_Drive[2] STR_Lifter_Movimot_Drive[2] STR_Gripper_Movimot_Drive[2] | K3: No | L3: Yes | M3: Yes | P3: CT Start No | Q3: 1
A4: =IF(ISNUMBER(SEARCH("CT",B4)),"1"&MID(B4,2,FIND("CT",B4)-2)&RIGHT(B4,1),MID(B4,2,FIND("C",B4)-2)&RIGHT(B4,1)) -> 33 | B4: B3C3 | C4: Inbound | D4: 1 | E4: =IF(ISNUMBER(SEARCH("CT",B4)), "CrossTransferStation[" & (Q$3 + COUNTIF($B$2:B4,"*CT*")-1) & "]", IF(AND(ISNUMBER(SEARCH("C",B4)),NOT(ISNUMBER(SEARCH("CT",B4)))), "ConveyorStation[" & (Q$2 + COUNTIF($B$2:B4,"*C*") - COUNTIF($B$2:B4,"*CT*")-1) & "]", "")) -> ConveyorStation[3] | J4: CNV_Movimot_Drive[3] | K4: No | L4: No | M4: No
A5: =IF(ISNUMBER(SEARCH("CT",B5)),"1"&MID(B5,2,FIND("CT",B5)-2)&RIGHT(B5,1),MID(B5,2,FIND("C",B5)-2)&RIGHT(B5,1)) -> 131 | B5: B3CT1 | C5: Inbound | D5: 1 | E5: =IF(ISNUMBER(SEARCH("CT",B5)), "CrossTransferStation[" & (Q$3 + COUNTIF($B$2:B5,"*CT*")-1) & "]", IF(AND(ISNUMBER(SEARCH("C",B5)),NOT(ISNUMBER(SEARCH("CT",B5)))), "ConveyorStation[" & (Q$2 + COUNTIF($B$2:B5,"*C*") - COUNTIF($B$2:B5,"*CT*")-1) & "]", "")) -> CrossTransferStation[1] | F5: Decision[1] | J5: CT_Movifit_Drive[1] CT_Moviswitch_Drive[1] CT_SP_Barcode_Scanner[1] | K5: Yes | L5: Yes | M5: Yes
A6: =IF(ISNUMBER(SEARCH("CT",B6)),"1"&MID(B6,2,FIND("CT",B6)-2)&RIGHT(B6,1),MID(B6,2,FIND("C",B6)-2)&RIGHT(B6,1)) -> 41 | B6: B4C1 | C6: Inbound | D6: 1 | E6: =IF(ISNUMBER(SEARCH("CT",B6)), "CrossTransferStation[" & (Q$3 + COUNTIF($B$2:B6,"*CT*")-1) & "]", IF(AND(ISNUMBER(SEARCH("C",B6)),NOT(ISNUMBER(SEARCH("CT",B6)))), "ConveyorStation[" & (Q$2 + COUNTIF($B$2:B6,"*C*") - COUNTIF($B$2:B6,"*CT*")-1) & "]", "")) -> ConveyorStation[4] | F6: LoadingStation[2] | J6: CNV_Movimot_Drive[4] | K6: No | L6: Yes | M6: No | P6: Name | Q6: Min | R6: Max | S6: No of Spare | T6: Next Stn No
A7: =IF(ISNUMBER(SEARCH("CT",B7)),"1"&MID(B7,2,FIND("CT",B7)-2)&RIGHT(B7,1),MID(B7,2,FIND("C",B7)-2)&RIGHT(B7,1)) -> 42 | B7: B4C2 | C7: Inbound | D7: 1 | E7: =IF(ISNUMBER(SEARCH("CT",B7)), "CrossTransferStation[" & (Q$3 + COUNTIF($B$2:B7,"*CT*")-1) & "]", IF(AND(ISNUMBER(SEARCH("C",B7)),NOT(ISNUMBER(SEARCH("CT",B7)))), "ConveyorStation[" & (Q$2 + COUNTIF($B$2:B7,"*C*") - COUNTIF($B$2:B7,"*CT*")-1) & "]", "")) -> ConveyorStation[5] | F7: StackDestackStation[4] | J7: CNV_Movimot_Drive[5] STR_Lifter_Movimot_Drive[5] STR_Gripper_Movimot_Drive[5] | K7: No | L7: Yes | M7: Yes | P7: ConveyorStation | Q7: 1 | R7: 34 | S7: 10 | T7: =SUM(R7:S7)+1 -> 45 | U7: =T7-S7-Q7 -> 34
A8: =IF(ISNUMBER(SEARCH("CT",B8)),"1"&MID(B8,2,FIND("CT",B8)-2)&RIGHT(B8,1),MID(B8,2,FIND("C",B8)-2)&RIGHT(B8,1)) -> 43 | B8: B4C3 | C8: Inbound | D8: 1 | E8: =IF(ISNUMBER(SEARCH("CT",B8)), "CrossTransferStation[" & (Q$3 + COUNTIF($B$2:B8,"*CT*")-1) & "]", IF(AND(ISNUMBER(SEARCH("C",B8)),NOT(ISNUMBER(SEARCH("CT",B8)))), "ConveyorStation[" & (Q$2 + COUNTIF($B$2:B8,"*C*") - COUNTIF($B$2:B8,"*CT*")-1) & "]", "")) -> ConveyorStation[6] | J8: CNV_Movimot_Drive[6] | K8: No | L8: No | M8: No | P8: CrossTransferStation | Q8: 1 | R8: 8 | S8: 10 | T8: =SUM(R8:S8)+1 -> 19 | U8: =T8-S8-Q8 -> 8
A9: =IF(ISNUMBER(SEARCH("CT",B9)),"1"&MID(B9,2,FIND("CT",B9)-2)&RIGHT(B9,1),MID(B9,2,FIND("C",B9)-2)&RIGHT(B9,1)) -> 141 | B9: B4CT1 | C9: Inbound | D9: 1 | E9: =IF(ISNUMBER(SEARCH("CT",B9)), "CrossTransferStation[" & (Q$3 + COUNTIF($B$2:B9,"*CT*")-1) & "]", IF(AND(ISNUMBER(SEARCH("C",B9)),NOT(ISNUMBER(SEARCH("CT",B9)))), "ConveyorStation[" & (Q$2 + COUNTIF($B$2:B9,"*C*") - COUNTIF($B$2:B9,"*CT*")-1) & "]", "")) -> CrossTransferStation[2] | F9: Decision[2] | J9: CT_Movifit_Drive[2] CT_Moviswitch_Drive[2] CT_SP_Barcode_Scanner[2] | K9: Yes | L9: Yes | M9: Yes | P9: Decision | Q9: 1 | R9: 8 | S9: 10 | T9: =SUM(R9:S9)+1 -> 19 | U9: =T9-S9-Q9 -> 8
A10: =IF(ISNUMBER(SEARCH("CT",B10)),"1"&MID(B10,2,FIND("CT",B10)-2)&RIGHT(B10,1),MID(B10,2,FIND("C",B10)-2)&RIGHT(B10,1)) -> 51 | B10: B5C1 | C10: Inbound | D10: 1 | E10: =IF(ISNUMBER(SEARCH("CT",B10)), "CrossTransferStation[" & (Q$3 + COUNTIF($B$2:B10,"*CT*")-1) & "]", IF(AND(ISNUMBER(SEARCH("C",B10)),NOT(ISNUMBER(SEARCH("CT",B10)))), "ConveyorStation[" & (Q$2 + COUNTIF($B$2:B10,"*C*") - COUNTIF($B$2:B10,"*CT*")-1) & "]", "")) -> ConveyorStation[7] | F10: LoadingStation[3] | J10: CNV_Movimot_Drive[7] | K10: No | L10: Yes | M10: No | P10: LoadingStation | Q10: 1 | R10: 5 | S10: 10 | T10: =SUM(R10:S10)+1 -> 16 | U10: =T10-S10-Q10 -> 5
A11: =IF(ISNUMBER(SEARCH("CT",B11)),"1"&MID(B11,2,FIND("CT",B11)-2)&RIGHT(B11,1),MID(B11,2,FIND("C",B11)-2)&RIGHT(B11,1)) -> 52 | B11: B5C2 | C11: Inbound | D11: 1 | E11: =IF(ISNUMBER(SEARCH("CT",B11)), "CrossTransferStation[" & (Q$3 + COUNTIF($B$2:B11,"*CT*")-1) & "]", IF(AND(ISNUMBER(SEARCH("C",B11)),NOT(ISNUMBER(SEARCH("CT",B11)))), "ConveyorStation[" & (Q$2 + COUNTIF($B$2:B11,"*C*") - COUNTIF($B$2:B11,"*CT*")-1) & "]", "")) -> ConveyorStation[8] | F11: LoadingStation[4] | J11: CNV_Movimot_Drive[8] | K11: No | L11: Yes | M11: No | P11: UnloadingStation | Q11: 1 | R11: 5 | S11: 10 | T11: =SUM(R11:S11)+1 -> 16 | U11: =T11-S11-Q11 -> 5
A12: =IF(ISNUMBER(SEARCH("CT",B12)),"1"&MID(B12,2,FIND("CT",B12)-2)&RIGHT(B12,1),MID(B12,2,FIND("C",B12)-2)&RIGHT(B12,1)) -> 53 | B12: B5C3 | C12: Inbound | D12: 1 | E12: =IF(ISNUMBER(SEARCH("CT",B12)), "CrossTransferStation[" & (Q$3 + COUNTIF($B$2:B12,"*CT*")-1) & "]", IF(AND(ISNUMBER(SEARCH("C",B12)),NOT(ISNUMBER(SEARCH("CT",B12)))), "ConveyorStation[" & (Q$2 + COUNTIF($B$2:B12,"*C*") - COUNTIF($B$2:B12,"*CT*")-1) & "]", "")) -> ConveyorStation[9] | J12: CNV_Movimot_Drive[9] | K12: No | L12: No | M12: No | P12: StackDestackStation | Q12: 1 | R12: 4 | S12: 10 | T12: =SUM(R12:S12)+1 -> 15 | U12: =T12-S12-Q12 -> 4
A13: =IF(ISNUMBER(SEARCH("CT",B13)),"1"&MID(B13,2,FIND("CT",B13)-2)&RIGHT(B13,1),MID(B13,2,FIND("C",B13)-2)&RIGHT(B13,1)) -> 151 | B13: B5CT1 | C13: Inbound | D13: 1 | E13: =IF(ISNUMBER(SEARCH("CT",B13)), "CrossTransferStation[" & (Q$3 + COUNTIF($B$2:B13,"*CT*")-1) & "]", IF(AND(ISNUMBER(SEARCH("C",B13)),NOT(ISNUMBER(SEARCH("CT",B13)))), "ConveyorStation[" & (Q$2 + COUNTIF($B$2:B13,"*C*") - COUNTIF($B$2:B13,"*CT*")-1) & "]", "")) -> CrossTransferStation[3] | F13: Decision[3] | J13: CT_Movifit_Drive[3] CT_Moviswitch_Drive[3] CT_SP_Barcode_Scanner[3] | K13: Yes | L13: Yes | M13: Yes | P13: ProfileCheckStation | Q13: 1 | R13: 1 | S13: 10 | T13: =SUM(R13:S13)+1 -> 12 | U13: =T13-S13-Q13 -> 1
A14: =IF(ISNUMBER(SEARCH("CT",B14)),"1"&MID(B14,2,FIND("CT",B14)-2)&RIGHT(B14,1),MID(B14,2,FIND("C",B14)-2)&RIGHT(B14,1)) -> 61 | B14: B6C1 | C14: Inbound | D14: 1 | E14: =IF(ISNUMBER(SEARCH("CT",B14)), "CrossTransferStation[" & (Q$3 + COUNTIF($B$2:B14,"*CT*")-1) & "]", IF(AND(ISNUMBER(SEARCH("C",B14)),NOT(ISNUMBER(SEARCH("CT",B14)))), "ConveyorStation[" & (Q$2 + COUNTIF($B$2:B14,"*C*") - COUNTIF($B$2:B14,"*CT*")-1) & "]", "")) -> ConveyorStation[10] | F14: LoadingStation[5] | J14: CNV_Movimot_Drive[10] | K14: No | L14: Yes | M14: No | P14: TurnTableStation
A15: =IF(ISNUMBER(SEARCH("CT",B15)),"1"&MID(B15,2,FIND("CT",B15)-2)&RIGHT(B15,1),MID(B15,2,FIND("C",B15)-2)&RIGHT(B15,1)) -> 62 | B15: B6C2 | C15: Inbound | D15: 1 | E15: =IF(ISNUMBER(SEARCH("CT",B15)), "CrossTransferStation[" & (Q$3 + COUNTIF($B$2:B15,"*CT*")-1) & "]", IF(AND(ISNUMBER(SEARCH("C",B15)),NOT(ISNUMBER(SEARCH("CT",B15)))), "ConveyorStation[" & (Q$2 + COUNTIF($B$2:B15,"*C*") - COUNTIF($B$2:B15,"*CT*")-1) & "]", "")) -> ConveyorStation[11] | F15: ProfileCheckStation[1] | J15: CNV_Movimot_Drive[11] CNV_SP_Barcode_Scanner[11] Tunnel_Scanner | K15: Yes | L15: No | M15: Yes | P15: LabellingStation | Q15: 1 | R15: 1 | S15: 10 | T15: =SUM(R15:S15)+1 -> 12 | U15: =T15-S15-Q15 -> 1
A16: =IF(ISNUMBER(SEARCH("CT",B16)),"1"&MID(B16,2,FIND("CT",B16)-2)&RIGHT(B16,1),MID(B16,2,FIND("C",B16)-2)&RIGHT(B16,1)) -> 63 | B16: B6C3 | C16: Inbound | D16: 1 | E16: =IF(ISNUMBER(SEARCH("CT",B16)), "CrossTransferStation[" & (Q$3 + COUNTIF($B$2:B16,"*CT*")-1) & "]", IF(AND(ISNUMBER(SEARCH("C",B16)),NOT(ISNUMBER(SEARCH("CT",B16)))), "ConveyorStation[" & (Q$2 + COUNTIF($B$2:B16,"*C*") - COUNTIF($B$2:B16,"*CT*")-1) & "]", "")) -> ConveyorStation[12] | F16: UnloadingStation[1] | J16: CNV_Movimot_Drive[12] | K16: No | L16: No | M16: Yes | P16: WrappingStation | Q16: 1 | R16: 1 | S16: 10 | T16: =SUM(R16:S16)+1 -> 12 | U16: =T16-S16-Q16 -> 1
A17: =IF(ISNUMBER(SEARCH("CT",B17)),"1"&MID(B17,2,FIND("CT",B17)-2)&RIGHT(B17,1),MID(B17,2,FIND("C",B17)-2)&RIGHT(B17,1)) -> 161 | B17: B6CT1 | C17: Inbound | D17: 1 | E17: =IF(ISNUMBER(SEARCH("CT",B17)), "CrossTransferStation[" & (Q$3 + COUNTIF($B$2:B17,"*CT*")-1) & "]", IF(AND(ISNUMBER(SEARCH("C",B17)),NOT(ISNUMBER(SEARCH("CT",B17)))), "ConveyorStation[" & (Q$2 + COUNTIF($B$2:B17,"*C*") - COUNTIF($B$2:B17,"*CT*")-1) & "]", "")) -> CrossTransferStation[4] | F17: Decision[4] | J17: CT_Movifit_Drive[4] CT_Moviswitch_Drive[4] | K17: No | L17: Yes | M17: No | P17: Zone
A18: =IF(ISNUMBER(SEARCH("CT",B18)),"1"&MID(B18,2,FIND("CT",B18)-2)&RIGHT(B18,1),MID(B18,2,FIND("C",B18)-2)&RIGHT(B18,1)) -> 162 | B18: B6CT2 | C18: Inbound | D18: 1 | E18: =IF(ISNUMBER(SEARCH("CT",B18)), "CrossTransferStation[" & (Q$3 + COUNTIF($B$2:B18,"*CT*")-1) & "]", IF(AND(ISNUMBER(SEARCH("C",B18)),NOT(ISNUMBER(SEARCH("CT",B18)))), "ConveyorStation[" & (Q$2 + COUNTIF($B$2:B18,"*C*") - COUNTIF($B$2:B18,"*CT*")-1) & "]", "")) -> CrossTransferStation[5] | F18: Decision[5] | J18: CT_Movifit_Drive[5] CT_Moviswitch_Drive[5] | K18: No | L18: No | M18: Yes
A19: =IF(ISNUMBER(SEARCH("CT",B19)),"1"&MID(B19,2,FIND("CT",B19)-2)&RIGHT(B19,1),MID(B19,2,FIND("C",B19)-2)&RIGHT(B19,1)) -> 71 | B19: B7C1 | C19: Inbound | D19: 1 | E19: =IF(ISNUMBER(SEARCH("CT",B19)), "CrossTransferStation[" & (Q$3 + COUNTIF($B$2:B19,"*CT*")-1) & "]", IF(AND(ISNUMBER(SEARCH("C",B19)),NOT(ISNUMBER(SEARCH("CT",B19)))), "ConveyorStation[" & (Q$2 + COUNTIF($B$2:B19,"*C*") - COUNTIF($B$2:B19,"*CT*")-1) & "]", "")) -> ConveyorStation[13] | F19: LabellingStation[1] | J19: CNV_Movimot_Drive[13] CNV_SP_Barcode_Scannerr[13] Labelling_ScannerOP[1] | K19: Yes | L19: No | M19: Yes
A20: =IF(ISNUMBER(SEARCH("CT",B20)),"1"&MID(B20,2,FIND("CT",B20)-2)&RIGHT(B20,1),MID(B20,2,FIND("C",B20)-2)&RIGHT(B20,1)) -> 72 | B20: B7C2 | C20: Inbound | D20: 1 | E20: =IF(ISNUMBER(SEARCH("CT",B20)), "CrossTransferStation[" & (Q$3 + COUNTIF($B$2:B20,"*CT*")-1) & "]", IF(AND(ISNUMBER(SEARCH("C",B20)),NOT(ISNUMBER(SEARCH("CT",B20)))), "ConveyorStation[" & (Q$2 + COUNTIF($B$2:B20,"*C*") - COUNTIF($B$2:B20,"*CT*")-1) & "]", "")) -> ConveyorStation[14] | F20: WrappingStation[1] | J20: CNV_Movimot_Drive[14] | K20: No | L20: No | M20: Yes
A21: =IF(ISNUMBER(SEARCH("CT",B21)),"1"&MID(B21,2,FIND("CT",B21)-2)&RIGHT(B21,1),MID(B21,2,FIND("C",B21)-2)&RIGHT(B21,1)) -> 73 | B21: B7C3 | C21: Inbound | D21: 1 | E21: =IF(ISNUMBER(SEARCH("CT",B21)), "CrossTransferStation[" & (Q$3 + COUNTIF($B$2:B21,"*CT*")-1) & "]", IF(AND(ISNUMBER(SEARCH("C",B21)),NOT(ISNUMBER(SEARCH("CT",B21)))), "ConveyorStation[" & (Q$2 + COUNTIF($B$2:B21,"*C*") - COUNTIF($B$2:B21,"*CT*")-1) & "]", "")) -> ConveyorStation[15] | J21: CNV_Movimot_Drive[15] | K21: No | L21: No | M21: No
A22: =IF(ISNUMBER(SEARCH("CT",B22)),"1"&MID(B22,2,FIND("CT",B22)-2)&RIGHT(B22,1),MID(B22,2,FIND("C",B22)-2)&RIGHT(B22,1)) -> 74 | B22: B7C4 | C22: Inbound | D22: 1 | E22: =IF(ISNUMBER(SEARCH("CT",B22)), "CrossTransferStation[" & (Q$3 + COUNTIF($B$2:B22,"*CT*")-1) & "]", IF(AND(ISNUMBER(SEARCH("C",B22)),NOT(ISNUMBER(SEARCH("CT",B22)))), "ConveyorStation[" & (Q$2 + COUNTIF($B$2:B22,"*C*") - COUNTIF($B$2:B22,"*CT*")-1) & "]", "")) -> ConveyorStation[16] | J22: CNV_Movimot_Drive[16] | K22: No | L22: No | M22: Yes
A23: =IF(ISNUMBER(SEARCH("CT",B23)),"1"&MID(B23,2,FIND("CT",B23)-2)&RIGHT(B23,1),MID(B23,2,FIND("C",B23)-2)&RIGHT(B23,1)) -> 81 | B23: B8C1 | C23: Inbound | D23: 1 | E23: =IF(ISNUMBER(SEARCH("CT",B23)), "CrossTransferStation[" & (Q$3 + COUNTIF($B$2:B23,"*CT*")-1) & "]", IF(AND(ISNUMBER(SEARCH("C",B23)),NOT(ISNUMBER(SEARCH("CT",B23)))), "ConveyorStation[" & (Q$2 + COUNTIF($B$2:B23,"*C*") - COUNTIF($B$2:B23,"*CT*")-1) & "]", "")) -> ConveyorStation[17] | F23: UnloadingStation[2] | J23: CNV_Movimot_Drive[17] | K23: No | L23: No | M23: Yes
A24: =IF(ISNUMBER(SEARCH("CT",B24)),"1"&MID(B24,2,FIND("CT",B24)-2)&RIGHT(B24,1),MID(B24,2,FIND("C",B24)-2)&RIGHT(B24,1)) -> 82 | B24: B8C2 | C24: Inbound | D24: 1 | E24: =IF(ISNUMBER(SEARCH("CT",B24)), "CrossTransferStation[" & (Q$3 + COUNTIF($B$2:B24,"*CT*")-1) & "]", IF(AND(ISNUMBER(SEARCH("C",B24)),NOT(ISNUMBER(SEARCH("CT",B24)))), "ConveyorStation[" & (Q$2 + COUNTIF($B$2:B24,"*C*") - COUNTIF($B$2:B24,"*CT*")-1) & "]", "")) -> ConveyorStation[18] | F24: UnloadingStation[3] | J24: CNV_Movimot_Drive[18] | K24: No | L24: No | M24: Yes
A25: =IF(ISNUMBER(SEARCH("CT",B25)),"1"&MID(B25,2,FIND("CT",B25)-2)&RIGHT(B25,1),MID(B25,2,FIND("C",B25)-2)&RIGHT(B25,1)) -> 83 | B25: B8C3 | C25: Inbound | D25: 1 | E25: =IF(ISNUMBER(SEARCH("CT",B25)), "CrossTransferStation[" & (Q$3 + COUNTIF($B$2:B25,"*CT*")-1) & "]", IF(AND(ISNUMBER(SEARCH("C",B25)),NOT(ISNUMBER(SEARCH("CT",B25)))), "ConveyorStation[" & (Q$2 + COUNTIF($B$2:B25,"*C*") - COUNTIF($B$2:B25,"*CT*")-1) & "]", "")) -> ConveyorStation[19] | J25: CNV_Movimot_Drive[19] | K25: No | L25: No | M25: No
A26: =IF(ISNUMBER(SEARCH("CT",B26)),"1"&MID(B26,2,FIND("CT",B26)-2)&RIGHT(B26,1),MID(B26,2,FIND("C",B26)-2)&RIGHT(B26,1)) -> 181 | B26: B8CT1 | C26: Inbound | D26: 1 | E26: =IF(ISNUMBER(SEARCH("CT",B26)), "CrossTransferStation[" & (Q$3 + COUNTIF($B$2:B26,"*CT*")-1) & "]", IF(AND(ISNUMBER(SEARCH("C",B26)),NOT(ISNUMBER(SEARCH("CT",B26)))), "ConveyorStation[" & (Q$2 + COUNTIF($B$2:B26,"*C*") - COUNTIF($B$2:B26,"*CT*")-1) & "]", "")) -> CrossTransferStation[6] | F26: Decision[6] | J26: CT_Movifit_Drive[6] CT_Moviswitch_Drive[6] CT_SP_Barcode_Scanner[6] | K26: Yes | L26: No | M26: Yes
A27: =IF(ISNUMBER(SEARCH("CT",B27)),"1"&MID(B27,2,FIND("CT",B27)-2)&RIGHT(B27,1),MID(B27,2,FIND("C",B27)-2)&RIGHT(B27,1)) -> 91 | B27: B9C1 | C27: Inbound | D27: 1 | E27: =IF(ISNUMBER(SEARCH("CT",B27)), "CrossTransferStation[" & (Q$3 + COUNTIF($B$2:B27,"*CT*")-1) & "]", IF(AND(ISNUMBER(SEARCH("C",B27)),NOT(ISNUMBER(SEARCH("CT",B27)))), "ConveyorStation[" & (Q$2 + COUNTIF($B$2:B27,"*C*") - COUNTIF($B$2:B27,"*CT*")-1) & "]", "")) -> ConveyorStation[20] | F27: UnloadingStation[4] | J27: CNV_Movimot_Drive[20] | K27: No | L27: No | M27: Yes
A28: =IF(ISNUMBER(SEARCH("CT",B28)),"1"&MID(B28,2,FIND("CT",B28)-2)&RIGHT(B28,1),MID(B28,2,FIND("C",B28)-2)&RIGHT(B28,1)) -> 92 | B28: B9C2 | C28: Inbound | D28: 1 | E28: =IF(ISNUMBER(SEARCH("CT",B28)), "CrossTransferStation[" & (Q$3 + COUNTIF($B$2:B28,"*CT*")-1) & "]", IF(AND(ISNUMBER(SEARCH("C",B28)),NOT(ISNUMBER(SEARCH("CT",B28)))), "ConveyorStation[" & (Q$2 + COUNTIF($B$2:B28,"*C*") - COUNTIF($B$2:B28,"*CT*")-1) & "]", "")) -> ConveyorStation[21] | F28: UnloadingStation[5] | J28: CNV_Movimot_Drive[21] | K28: No | L28: No | M28: Yes
A29: =IF(ISNUMBER(SEARCH("CT",B29)),"1"&MID(B29,2,FIND("CT",B29)-2)&RIGHT(B29,1),MID(B29,2,FIND("C",B29)-2)&RIGHT(B29,1)) -> 93 | B29: B9C3 | C29: Inbound | D29: 1 | E29: =IF(ISNUMBER(SEARCH("CT",B29)), "CrossTransferStation[" & (Q$3 + COUNTIF($B$2:B29,"*CT*")-1) & "]", IF(AND(ISNUMBER(SEARCH("C",B29)),NOT(ISNUMBER(SEARCH("CT",B29)))), "ConveyorStation[" & (Q$2 + COUNTIF($B$2:B29,"*C*") - COUNTIF($B$2:B29,"*CT*")-1) & "]", "")) -> ConveyorStation[22] | J29: CNV_Movimot_Drive[22] | K29: No | L29: No | M29: No
A30: =IF(ISNUMBER(SEARCH("CT",B30)),"1"&MID(B30,2,FIND("CT",B30)-2)&RIGHT(B30,1),MID(B30,2,FIND("C",B30)-2)&RIGHT(B30,1)) -> 191 | B30: B9CT1 | C30: Inbound | D30: 1 | E30: =IF(ISNUMBER(SEARCH("CT",B30)), "CrossTransferStation[" & (Q$3 + COUNTIF($B$2:B30,"*CT*")-1) & "]", IF(AND(ISNUMBER(SEARCH("C",B30)),NOT(ISNUMBER(SEARCH("CT",B30)))), "ConveyorStation[" & (Q$2 + COUNTIF($B$2:B30,"*C*") - COUNTIF($B$2:B30,"*CT*")-1) & "]", "")) -> CrossTransferStation[7] | F30: Decision[7] | J30: CT_Movifit_Drive[7] CT_Moviswitch_Drive[7] CT_SP_Barcode_Scanner[7] | K30: Yes | L30: No | M30: Yes
A31: =IF(ISNUMBER(SEARCH("CT",B31)),"1"&MID(B31,2,FIND("CT",B31)-2)&RIGHT(B31,1),MID(B31,2,FIND("C",B31)-2)&RIGHT(B31,1)) -> 192 | B31: B9CT2 | C31: Inbound | D31: 1 | E31: =IF(ISNUMBER(SEARCH("CT",B31)), "CrossTransferStation[" & (Q$3 + COUNTIF($B$2:B31,"*CT*")-1) & "]", IF(AND(ISNUMBER(SEARCH("C",B31)),NOT(ISNUMBER(SEARCH("CT",B31)))), "ConveyorStation[" & (Q$2 + COUNTIF($B$2:B31,"*C*") - COUNTIF($B$2:B31,"*CT*")-1) & "]", "")) -> CrossTransferStation[8] | F31: Decision[8] | J31: CT_Movifit_Drive[8] CT_Moviswitch_Drive[8] CT_SP_Barcode_Scanner[8] | K31: Yes | L31: No | M31: Yes
A32: =IF(ISNUMBER(SEARCH("CT",B32)),"1"&MID(B32,2,FIND("CT",B32)-2)&RIGHT(B32,1),MID(B32,2,FIND("C",B32)-2)&RIGHT(B32,1)) -> 101 | B32: B10C1 | C32: Inbound | D32: 1 | E32: =IF(ISNUMBER(SEARCH("CT",B32)), "CrossTransferStation[" & (Q$3 + COUNTIF($B$2:B32,"*CT*")-1) & "]", IF(AND(ISNUMBER(SEARCH("C",B32)),NOT(ISNUMBER(SEARCH("CT",B32)))), "ConveyorStation[" & (Q$2 + COUNTIF($B$2:B32,"*C*") - COUNTIF($B$2:B32,"*CT*")-1) & "]", "")) -> ConveyorStation[23] | J32: CNV_Movimot_Drive[23] | K32: No | L32: No | M32: No
A33: =IF(ISNUMBER(SEARCH("CT",B33)),"1"&MID(B33,2,FIND("CT",B33)-2)&RIGHT(B33,1),MID(B33,2,FIND("C",B33)-2)&RIGHT(B33,1)) -> 102 | B33: B10C2 | C33: Inbound | D33: 1 | E33: =IF(ISNUMBER(SEARCH("CT",B33)), "CrossTransferStation[" & (Q$3 + COUNTIF($B$2:B33,"*CT*")-1) & "]", IF(AND(ISNUMBER(SEARCH("C",B33)),NOT(ISNUMBER(SEARCH("CT",B33)))), "ConveyorStation[" & (Q$2 + COUNTIF($B$2:B33,"*C*") - COUNTIF($B$2:B33,"*CT*")-1) & "]", "")) -> ConveyorStation[24] | J33: CNV_Movimot_Drive[24] | K33: No | L33: No | M33: No
A34: =IF(ISNUMBER(SEARCH("CT",B34)),"1"&MID(B34,2,FIND("CT",B34)-2)&RIGHT(B34,1),MID(B34,2,FIND("C",B34)-2)&RIGHT(B34,1)) -> 103 | B34: B10C3 | C34: Inbound | D34: 1 | E34: =IF(ISNUMBER(SEARCH("CT",B34)), "CrossTransferStation[" & (Q$3 + COUNTIF($B$2:B34,"*CT*")-1) & "]", IF(AND(ISNUMBER(SEARCH("C",B34)),NOT(ISNUMBER(SEARCH("CT",B34)))), "ConveyorStation[" & (Q$2 + COUNTIF($B$2:B34,"*C*") - COUNTIF($B$2:B34,"*CT*")-1) & "]", "")) -> ConveyorStation[25] | J34: CNV_Movimot_Drive[25] | K34: No | L34: No | M34: No
